Workbook

Sheet Journal
A1: JOURNAL COMPTABLE - Exercice 2025
A2: Date | B2: Piece | C2: Code | D2: Compte | E2: Libelle ecriture | F2: Debit | G2: Credit
A3: 01/01/2025 | B3: OUV | C3: 1000 | D3: Tresorerie | E3: Solde d'ouverture | F3: 50000
A4: 01/01/2025 | B4: OUV | C4: 1100 | D4: Clients | E4: Solde d'ouverture | F4: 30000
A5: 01/01/2025 | B5: OUV | C5: 1200 | D5: Stocks | E5: Solde d'ouverture | F5: 40000
A6: 01/01/2025 | B6: OUV | C6: 1500 | D6: Immobilisations corporelles (brut) | E6: Solde d'ouverture | F6: 200000
A7: 01/01/2025 | B7: OUV | C7: 1590 | D7: Amortissements cumules | E7: Solde d'ouverture | G7: 60000
A8: 01/01/2025 | B8: OUV | C8: 2000 | D8: Fournisseurs | E8: Solde d'ouverture | G8: 25000
A9: 01/01/2025 | B9: OUV | C9: 2500 | D9: Emprunts | E9: Solde d'ouverture | G9: 80000
A10: 01/01/2025 | B10: OUV | C10: 3000 | D10: Capital social | E10: Solde d'ouverture | G10: 100000
A11: 01/01/2025 | B11: OUV | C11: 3100 | D11: Resultats non distribues (ouv.) | E11: Solde d'ouverture | G11: 55000
A12: 15/02/2025 | B12: VT-01 | C12: 1100 | D12: Clients | E12: Ventes a credit | F12: 300000
A13: 15/02/2025 | B13: VT-01 | C13: 4000 | D13: Produits (ventes) | E13: Ventes a credit | G13: 300000
A14: 20/03/2025 | B14: ENC-01 | C14: 1000 | D14: Tresorerie | E14: Encaissement clients | F14: 290000
A15: 20/03/2025 | B15: ENC-01 | C15: 1100 | D15: Clients | E15: Encaissement clients | G15: 290000
A16: 05/04/2025 | B16: ACH-01 | C16: 1200 | D16: Stocks | E16: Achats de marchandises | F16: 160000
A17: 05/04/2025 | B17: ACH-01 | C17: 2000 | D17: Fournisseurs | E17: Achats de marchandises | G17: 160000
A18: 30/06/2025 | B18: CV-01 | C18: 5000 | D18: Cout des ventes | E18: Sortie de stock vendu | F18: 170000
A19: 30/06/2025 | B19: CV-01 | C19: 1200 | D19: Stocks | E19: Sortie de stock vendu | G19: 170000
A20: 10/07/2025 | B20: PAY-01 | C20: 2000 | D20: Fournisseurs | E20: Reglement fournisseurs | F20: 165000
A21: 10/07/2025 | B21: PAY-01 | C21: 1000 | D21: Tresorerie | E21: Reglement fournisseurs | G21: 165000
A22: 31/07/2025 | B22: SAL-01 | C22: 5100 | D22: Charges de personnel | E22: Salaires | F22: 60000
A23: 31/07/2025 | B23: SAL-01 | C23: 1000 | D23: Tresorerie | E23: Salaires | G23: 60000
A24: 31/08/2025 | B24: AUT-01 | C24: 5300 | D24: Autres charges | E24: Charges diverses | F24: 25000
A25: 31/08/2025 | B25: AUT-01 | C25: 1000 | D25: Tresorerie | E25: Charges diverses | G25: 25000
A26: 30/09/2025 | B26: AM-01 | C26: 5200 | D26: Dotations amortissements | E26: Dotation amortissement | F26: 20000
A27: 30/09/2025 | B27: AM-01 | C27: 1590 | D27: Amortissements cumules | E27: Dotation amortissement | G27: 20000
A28: 15/10/2025 | B28: INV-01 | C28: 1500 | D28: Immobilisations corporelles (brut) | E28: Acquisition materiel | F28: 30000
A29: 15/10/2025 | B29: INV-01 | C29: 1000 | D29: Tresorerie | E29: Acquisition materiel | G29: 30000
A30: 31/10/2025 | B30: FIN-01 | C30: 6000 | D30: Charges financieres | E30: Interets emprunt | F30: 8000
A31: 31/10/2025 | B31: FIN-01 | C31: 1000 | D31: Tresorerie | E31: Interets emprunt | G31: 8000
A32: 01/11/2025 | B32: EMP-01 | C32: 1000 | D32: Tresorerie | E32: Nouvel emprunt | F32: 20000
A33: 01/11/2025 | B33: EMP-01 | C33: 2500 | D33: Emprunts | E33: Nouvel emprunt | G33: 20000
A34: 15/12/2025 | B34: IS-01 | C34: 7000 | D34: Impot sur le resultat | E34: Charge d'impot | F34: 12000
A35: 15/12/2025 | B35: IS-01 | C35: 2100 | D35: Impot a payer | E35: Charge d'impot | G35: 12000
A36: 20/12/2025 | B36: IS-02 | C36: 2100 | D36: Impot a payer | E36: Paiement acompte impot | F36: 9000
A37: 20/12/2025 | B37: IS-02 | C37: 1000 | D37: Tresorerie | E37: Paiement acompte impot | G37: 9000
A38: 28/12/2025 | B38: DIV-01 | C38: 3100 | D38: Resultats non distribues (ouv.) | E38: Dividendes verses | F38: 15000
A39: 28/12/2025 | B39: DIV-01 | C39: 1000 | D39: Tresorerie | E39: Dividendes verses | G39: 15000
E40: TOTAUX | F40: =SUM(F3:F39) | G40: =SUM(G3:G39)
...

Sheet Balance
A1: BALANCE DE VERIFICATION - Exercice 2025
A2: Code | B2: Compte | C2: Total debit | D2: Total credit | E2: Solde debiteur | F2: Solde crediteur
A3: 1000 | B3: Tresorerie | C3: =SUMIF(Journal!$C:$C,A3,Journal!$F:$F) | D3: =SUMIF(Journal!$C:$C,A3,Journal!$G:$G) | E3: =IF(C3-D3>0,C3-D3,0) | F3: =IF(D3-C3>0,D3-C3,0)
A4: 1100 | B4: Clients | C4: =SUMIF(Journal!$C:$C,A4,Journal!$F:$F) | D4: =SUMIF(Journal!$C:$C,A4,Journal!$G:$G) | E4: =IF(C4-D4>0,C4-D4,0) | F4: =IF(D4-C4>0,D4-C4,0)
A5: 1200 | B5: Stocks | C5: =SUMIF(Journal!$C:$C,A5,Journal!$F:$F) | D5: =SUMIF(Journal!$C:$C,A5,Journal!$G:$G) | E5: =IF(C5-D5>0,C5-D5,0) | F5: =IF(D5-C5>0,D5-C5,0)
A6: 1500 | B6: Immobilisations corporelles (brut) | C6: =SUMIF(Journal!$C:$C,A6,Journal!$F:$F) | D6: =SUMIF(Journal!$C:$C,A6,Journal!$G:$G) | E6: =IF(C6-D6>0,C6-D6,0) | F6: =IF(D6-C6>0,D6-C6,0)
A7: 1590 | B7: Amortissements cumules | C7: =SUMIF(Journal!$C:$C,A7,Journal!$F:$F) | D7: =SUMIF(Journal!$C:$C,A7,Journal!$G:$G) | E7: =IF(C7-D7>0,C7-D7,0) | F7: =IF(D7-C7>0,D7-C7,0)
A8: 2000 | B8: Fournisseurs | C8: =SUMIF(Journal!$C:$C,A8,Journal!$F:$F) | D8: =SUMIF(Journal!$C:$C,A8,Journal!$G:$G) | E8: =IF(C8-D8>0,C8-D8,0) | F8: =IF(D8-C8>0,D8-C8,0)
A9: 2100 | B9: Impot a payer | C9: =SUMIF(Journal!$C:$C,A9,Journal!$F:$F) | D9: =SUMIF(Journal!$C:$C,A9,Journal!$G:$G) | E9: =IF(C9-D9>0,C9-D9,0) | F9: =IF(D9-C9>0,D9-C9,0)
A10: 2500 | B10: Emprunts | C10: =SUMIF(Journal!$C:$C,A10,Journal!$F:$F) | D10: =SUMIF(Journal!$C:$C,A10,Journal!$G:$G) | E10: =IF(C10-D10>0,C10-D10,0) | F10: =IF(D10-C10>0,D10-C10,0)
A11: 3000 | B11: Capital social | C11: =SUMIF(Journal!$C:$C,A11,Journal!$F:$F) | D11: =SUMIF(Journal!$C:$C,A11,Journal!$G:$G) | E11: =IF(C11-D11>0,C11-D11,0) | F11: =IF(D11-C11>0,D11-C11,0)
A12: 3100 | B12: Resultats non distribues (ouv.) | C12: =SUMIF(Journal!$C:$C,A12,Journal!$F:$F) | D12: =SUMIF(Journal!$C:$C,A12,Journal!$G:$G) | E12: =IF(C12-D12>0,C12-D12,0) | F12: =IF(D12-C12>0,D12-C12,0)
A13: 4000 | B13: Produits (ventes) | C13: =SUMIF(Journal!$C:$C,A13,Journal!$F:$F) | D13: =SUMIF(Journal!$C:$C,A13,Journal!$G:$G) | E13: =IF(C13-D13>0,C13-D13,0) | F13: =IF(D13-C13>0,D13-C13,0)
A14: 5000 | B14: Cout des ventes | C14: =SUMIF(Journal!$C:$C,A14,Journal!$F:$F) | D14: =SUMIF(Journal!$C:$C,A14,Journal!$G:$G) | E14: =IF(C14-D14>0,C14-D14,0) | F14: =IF(D14-C14>0,D14-C14,0)
... A19: 7000 | B19: Impot sur le resultat | C19: =SUMIF(Journal!$C:$C,A19,Journal!$F:$F) | D19: =SUMIF(Journal!$C:$C,A19,Journal!$G:$G) | E19: =IF(C19-D19>0,C19-D19,0) | F19: =IF(D19-C19>0,D19-C19,0)
B20: TOTAUX | C20: =SUM(C3:C19) | D20: =SUM(D3:D19) | E20: =SUM(E3:E19) | F20: =SUM(F3:F19)

Sheet Resultat
A1: COMPTE DE RESULTAT (IFRS) - Exercice 2025
A2: Poste | B2: Montant
A3: Produits (chiffre d'affaires) | B3: =Balance!F13
A4: Cout des ventes | B4: =-Balance!E14
A5: Marge brute | B5: =B3+B4
A6: Charges de personnel | B6: =-Balance!E15
A7: Dotations aux amortissements | B7: =-Balance!E16
A8: Autres charges | B8: =-Balance!E17
A9: Resultat operationnel | B9: =B5+B6+B7+B8
A10: Charges financieres | B10: =-Balance!E18
A11: Resultat avant impot | B11: =B9+B10
A12: Impot sur le resultat | B12: =-Balance!E19
A13: Resultat net de l'exercice | B13: =B11+B12

Sheet Bilan
A1: ETAT DE LA SITUATION FINANCIERE (BILAN IFRS) au 31/12/2025
A2: Poste | B2: Montant
A3: ACTIF
A4: Actifs non courants
A5: Immobilisations corporelles (nettes) | B5: =Balance!E6-Balance!F7
A6: Total actifs non courants | B6: =B5
A7: Actifs courants
A8: Stocks | B8: =Balance!E5
A9: Clients et autres debiteurs | B9: =Balance!E4
A10: Tresorerie et equivalents | B10: =Balance!E3
A11: Total actifs courants | B11: =B8+B9+B10
A12: TOTAL ACTIF | B12: =B6+B11
A14: CAPITAUX PROPRES ET PASSIFS
A15: Capitaux propres
A16: Capital social | B16: =Balance!F11
A17: Resultats non distribues | B17: =Balance!F12+Resultat!B13
A18: Total capitaux propres | B18: =B16+B17
A19: Passifs non courants
A20: Emprunts | B20: =Balance!F10
A21: Total passifs non courants | B21: =B20
A22: Passifs courants
A23: Fournisseurs | B23: =Balance!F8
A24: Impot a payer | B24: =Balance!F9
A25: Total passifs courants | B25: =B23+B24
A26: TOTAL CAPITAUX PROPRES ET PASSIFS | B26: =B18+B21+B25
A27: Controle (Actif - Passif) | B27: =B12-B26

Sheet Tresorerie
A1: TABLEAU DES FLUX DE TRESORERIE (indirecte) - 2025
A2: Poste | B2: Montant | D2: Soldes d'ouverture (01/01) | E2: Valeur
A3: Flux lies a l'exploitation | D3: Clients | E3: 30000
A4: Resultat avant impot | B4: =Resultat!B11 | D4: Stocks | E4: 40000
A5: + Dotations aux amortissements | B5: =Balance!E16 | D5: Fournisseurs | E5: 25000
A6: + Charges financieres | B6: =Balance!E18 | D6: Immobilisations (brut) | E6: 200000
A7: Resultat avant variation du BFR | B7: =B4+B5+B6 | D7: Emprunts | E7: 80000
A8: Variation des clients | B8: =-(Balance!E4-E3) | D8: Tresorerie | E8: 50000
A9: Variation des stocks | B9: =-(Balance!E5-E4) | D9: Resultats non distribues | E9: 55000
A10: Variation des fournisseurs | B10: =Balance!F8-E5
A11: Tresorerie generee par l'exploitation | B11: =B7+B8+B9+B10
A12: Interets payes | B12: =-Balance!E18
A13: Impot paye | B13: =-(Balance!E19-Balance!F9)
A14: Flux net d'exploitation | B14: =B11+B12+B13
A15: Flux lies a l'investissement
A16: Acquisition d'immobilisations | B16: =-(Balance!E6-E6)
A17: Flux net d'investissement | B17: =B16
A18: Flux lies au financement
A19: Variation des emprunts | B19: =Balance!F10-E7
A20: Dividendes verses | B20: =-(E9-Balance!F12)
A21: Flux net de financement | B21: =B19+B20
A22: Variation nette de tresorerie | B22: =B14+B17+B21
A23: Tresorerie a l'ouverture | B23: =E8
A24: Tresorerie a la cloture | B24: =B23+B22
A25: Controle (vs bilan) | B25: =B24-Balance!E3

Sheet Ratios
A1: RATIOS FINANCIERS - Exercice 2025
A2: Ratio | B2: Valeur | C2: Formule / interpretation
A3: Liquidite generale | B3: =Bilan!B11/Bilan!B25 | C3: Actifs courants / Passifs courants
A4: Liquidite reduite (quick ratio) | B4: =(Bilan!B11-Bilan!B8)/Bilan!B25 | C4: (Actifs courants - Stocks) / Passifs courants
A5: Autonomie financiere | B5: =Bilan!B18/Bilan!B12 | C5: Capitaux propres / Total actif
A6: Endettement (Dettes fin./CP) | B6: =Bilan!B20/Bilan!B18 | C6: Emprunts / Capitaux propres
A7: Marge brute | B7: =Resultat!B5/Resultat!B3 | C7: Marge brute / Produits
A8: Marge operationnelle | B8: =Resultat!B9/Resultat!B3 | C8: Resultat operationnel / Produits
A9: Marge nette | B9: =Resultat!B13/Resultat!B3 | C9: Resultat net / Produits
A10: ROE (rentabilite des CP) | B10: =Resultat!B13/Bilan!B18 | C10: Resultat net / Capitaux propres
A11: ROA (rentabilite de l'actif) | B11: =Resultat!B13/Bilan!B12 | C11: Resultat net / Total actif
A12: Rotation des stocks | B12: =-Resultat!B4/Bilan!B8 | C12: Cout des ventes / Stocks
A13: Besoin en fonds de roulement | B13: =Bilan!B8+Bilan!B9-Bilan!B23 | C13: Stocks + Clients - Fournisseurs
