Workbook

Sheet Journal
A1: OHADA GENERAL JOURNAL - Year 2025
A2: Date | B2: Ref | C2: Account | D2: Account name | E2: Entry description | F2: Debit | G2: Credit | H2: Month
A3: 01/01/2025 | B3: OUV | C3: 24 | D3: Property, plant and equipment | E3: Opening balance | F3: 200000 | H3: =VALUE(MID(A3,4,2))
A4: 01/01/2025 | B4: OUV | C4: 31 | D4: Merchandise inventory | E4: Opening balance | F4: 40000 | H4: =VALUE(MID(A4,4,2))
A5: 01/01/2025 | B5: OUV | C5: 411 | D5: Trade receivables | E5: Opening balance | F5: 30000 | H5: =VALUE(MID(A5,4,2))
A6: 01/01/2025 | B6: OUV | C6: 52 | D6: Banks | E6: Opening balance | F6: 50000 | H6: =VALUE(MID(A6,4,2))
A7: 01/01/2025 | B7: OUV | C7: 28 | D7: Accumulated depreciation | E7: Opening balance | G7: 60000 | H7: =VALUE(MID(A7,4,2))
A8: 01/01/2025 | B8: OUV | C8: 401 | D8: Trade payables | E8: Opening balance | G8: 25000 | H8: =VALUE(MID(A8,4,2))
A9: 01/01/2025 | B9: OUV | C9: 16 | D9: Borrowings | E9: Opening balance | G9: 80000 | H9: =VALUE(MID(A9,4,2))
A10: 01/01/2025 | B10: OUV | C10: 101 | D10: Share capital | E10: Opening balance | G10: 100000 | H10: =VALUE(MID(A10,4,2))
A11: 01/01/2025 | B11: OUV | C11: 11 | D11: Reserves | E11: Opening balance | G11: 40000 | H11: =VALUE(MID(A11,4,2))
A12: 01/01/2025 | B12: OUV | C12: 12 | D12: Retained earnings | E12: Opening balance | G12: 15000 | H12: =VALUE(MID(A12,4,2))
A13: 15/02/2025 | B13: VT-01 | C13: 411 | D13: Trade receivables | E13: Credit sales | F13: 300000 | H13: =VALUE(MID(A13,4,2))
A14: 15/02/2025 | B14: VT-01 | C14: 701 | D14: Sales of goods | E14: Credit sales | G14: 300000 | H14: =VALUE(MID(A14,4,2))
A15: 20/03/2025 | B15: ENC-01 | C15: 52 | D15: Banks | E15: Cash collected from customers | F15: 290000 | H15: =VALUE(MID(A15,4,2))
A16: 20/03/2025 | B16: ENC-01 | C16: 411 | D16: Trade receivables | E16: Cash collected from customers | G16: 290000 | H16: =VALUE(MID(A16,4,2))
A17: 05/04/2025 | B17: ACH-01 | C17: 601 | D17: Purchases of goods | E17: Credit purchases | F17: 160000 | H17: =VALUE(MID(A17,4,2))
A18: 05/04/2025 | B18: ACH-01 | C18: 401 | D18: Trade payables | E18: Credit purchases | G18: 160000 | H18: =VALUE(MID(A18,4,2))
A19: 10/07/2025 | B19: PAY-01 | C19: 401 | D19: Trade payables | E19: Payment to suppliers | F19: 165000 | H19: =VALUE(MID(A19,4,2))
A20: 10/07/2025 | B20: PAY-01 | C20: 52 | D20: Banks | E20: Payment to suppliers | G20: 165000 | H20: =VALUE(MID(A20,4,2))
A21: 31/07/2025 | B21: SAL-01 | C21: 66 | D21: Personnel expenses | E21: Salaries | F21: 60000 | H21: =VALUE(MID(A21,4,2))
A22: 31/07/2025 | B22: SAL-01 | C22: 52 | D22: Banks | E22: Salaries | G22: 60000 | H22: =VALUE(MID(A22,4,2))
A23: 31/08/2025 | B23: SE-01 | C23: 62 | D23: External services | E23: External services rendered | F23: 25000 | H23: =VALUE(MID(A23,4,2))
A24: 31/08/2025 | B24: SE-01 | C24: 52 | D24: Banks | E24: External services rendered | G24: 25000 | H24: =VALUE(MID(A24,4,2))
A25: 15/10/2025 | B25: INV-01 | C25: 24 | D25: Property, plant and equipment | E25: Equipment purchase | F25: 30000 | H25: =VALUE(MID(A25,4,2))
A26: 15/10/2025 | B26: INV-01 | C26: 52 | D26: Banks | E26: Equipment purchase | G26: 30000 | H26: =VALUE(MID(A26,4,2))
A27: 31/10/2025 | B27: FIN-01 | C27: 671 | D27: Financial expenses | E27: Loan interest | F27: 8000 | H27: =VALUE(MID(A27,4,2))
A28: 31/10/2025 | B28: FIN-01 | C28: 52 | D28: Banks | E28: Loan interest | G28: 8000 | H28: =VALUE(MID(A28,4,2))
A29: 01/11/2025 | B29: EMP-01 | C29: 52 | D29: Banks | E29: New loan | F29: 20000 | H29: =VALUE(MID(A29,4,2))
A30: 01/11/2025 | B30: EMP-01 | C30: 16 | D30: Borrowings | E30: New loan | G30: 20000 | H30: =VALUE(MID(A30,4,2))
A31: 15/12/2025 | B31: IS-01 | C31: 891 | D31: Income tax | E31: Income tax charge | F31: 12000 | H31: =VALUE(MID(A31,4,2))
A32: 15/12/2025 | B32: IS-01 | C32: 44 | D32: State, income tax | E32: Income tax charge | G32: 12000 | H32: =VALUE(MID(A32,4,2))
A33: 20/12/2025 | B33: IS-02 | C33: 44 | D33: State, income tax | E33: Tax installment payment | F33: 9000 | H33: =VALUE(MID(A33,4,2))
A34: 20/12/2025 | B34: IS-02 | C34: 52 | D34: Banks | E34: Tax installment payment | G34: 9000 | H34: =VALUE(MID(A34,4,2))
A35: 28/12/2025 | B35: DIV-01 | C35: 12 | D35: Retained earnings | E35: Dividends paid | F35: 15000 | H35: =VALUE(MID(A35,4,2))
A36: 28/12/2025 | B36: DIV-01 | C36: 52 | D36: Banks | E36: Dividends paid | G36: 15000 | H36: =VALUE(MID(A36,4,2))
A37: 31/12/2025 | B37: AM-01 | C37: 681 | D37: Depreciation allowances | E37: Period depreciation | F37: 20000 | H37: =VALUE(MID(A37,4,2))
A38: 31/12/2025 | B38: AM-01 | C38: 28 | D38: Accumulated depreciation | E38: Period depreciation | G38: 20000 | H38: =VALUE(MID(A38,4,2))
A39: 31/12/2025 | B39: VS-01 | C39: 6031 | D39: Change in merchandise inventory | E39: Net inventory decrease | F39: 10000 | H39: =VALUE(MID(A39,4,2))
A40: 31/12/2025 | B40: VS-01 | C40: 31 | D40: Merchandise inventory | E40: Net inventory decrease | G40: 10000 | H40: =VALUE(MID(A40,4,2))
...

Sheet Balance
A1: OHADA 6-COLUMN TRIAL BALANCE - Year 2025
A2: Account | B2: Account name | C2: Opening Debit | D2: Opening Credit | E2: Movements Debit | F2: Movements Credit | G2: Closing Debit | H2: Closing Credit
A3: 101 | B3: Share capital | C3: =SUMIFS(Journal!$F:$F,Journal!$C:$C,A3,Journal!$B:$B,"OUV") | D3: =SUMIFS(Journal!$G:$G,Journal!$C:$C,A3,Journal!$B:$B,"OUV") | E3: =SUMIFS(Journal!$F:$F,Journal!$C:$C,A3,Journal!$B:$B,"<>OUV") | F3: =SUMIFS(Journal!$G:$G,Journal!$C:$C,A3,Journal!$B:$B,"<>OUV") | G3: =IF((C3+E3)-(D3+F3)>0,(C3+E3)-(D3+F3),0) | H3: =IF((D3+F3)-(C3+E3)>0,(D3+F3)-(C3+E3),0)
A4: 11 | B4: Reserves | C4: =SUMIFS(Journal!$F:$F,Journal!$C:$C,A4,Journal!$B:$B,"OUV") | D4: =SUMIFS(Journal!$G:$G,Journal!$C:$C,A4,Journal!$B:$B,"OUV") | E4: =SUMIFS(Journal!$F:$F,Journal!$C:$C,A4,Journal!$B:$B,"<>OUV") | F4: =SUMIFS(Journal!$G:$G,Journal!$C:$C,A4,Journal!$B:$B,"<>OUV") | G4: =IF((C4+E4)-(D4+F4)>0,(C4+E4)-(D4+F4),0) | H4: =IF((D4+F4)-(C4+E4)>0,(D4+F4)-(C4+E4),0)
A5: 12 | B5: Retained earnings | C5: =SUMIFS(Journal!$F:$F,Journal!$C:$C,A5,Journal!$B:$B,"OUV") | D5: =SUMIFS(Journal!$G:$G,Journal!$C:$C,A5,Journal!$B:$B,"OUV") | E5: =SUMIFS(Journal!$F:$F,Journal!$C:$C,A5,Journal!$B:$B,"<>OUV") | F5: =SUMIFS(Journal!$G:$G,Journal!$C:$C,A5,Journal!$B:$B,"<>OUV") | G5: =IF((C5+E5)-(D5+F5)>0,(C5+E5)-(D5+F5),0) | H5: =IF((D5+F5)-(C5+E5)>0,(D5+F5)-(C5+E5),0)
A6: 16 | B6: Borrowings | C6: =SUMIFS(Journal!$F:$F,Journal!$C:$C,A6,Journal!$B:$B,"OUV") | D6: =SUMIFS(Journal!$G:$G,Journal!$C:$C,A6,Journal!$B:$B,"OUV") | E6: =SUMIFS(Journal!$F:$F,Journal!$C:$C,A6,Journal!$B:$B,"<>OUV") | F6: =SUMIFS(Journal!$G:$G,Journal!$C:$C,A6,Journal!$B:$B,"<>OUV") | G6: =IF((C6+E6)-(D6+F6)>0,(C6+E6)-(D6+F6),0) | H6: =IF((D6+F6)-(C6+E6)>0,(D6+F6)-(C6+E6),0)
A7: 24 | B7: PP&E (gross) | C7: =SUMIFS(Journal!$F:$F,Journal!$C:$C,A7,Journal!$B:$B,"OUV") | D7: =SUMIFS(Journal!$G:$G,Journal!$C:$C,A7,Journal!$B:$B,"OUV") | E7: =SUMIFS(Journal!$F:$F,Journal!$C:$C,A7,Journal!$B:$B,"<>OUV") | F7: =SUMIFS(Journal!$G:$G,Journal!$C:$C,A7,Journal!$B:$B,"<>OUV") | G7: =IF((C7+E7)-(D7+F7)>0,(C7+E7)-(D7+F7),0) | H7: =IF((D7+F7)-(C7+E7)>0,(D7+F7)-(C7+E7),0)
A8: 28 | B8: Accumulated depreciation | C8: =SUMIFS(Journal!$F:$F,Journal!$C:$C,A8,Journal!$B:$B,"OUV") | D8: =SUMIFS(Journal!$G:$G,Journal!$C:$C,A8,Journal!$B:$B,"OUV") | E8: =SUMIFS(Journal!$F:$F,Journal!$C:$C,A8,Journal!$B:$B,"<>OUV") | F8: =SUMIFS(Journal!$G:$G,Journal!$C:$C,A8,Journal!$B:$B,"<>OUV") | G8: =IF((C8+E8)-(D8+F8)>0,(C8+E8)-(D8+F8),0) | H8: =IF((D8+F8)-(C8+E8)>0,(D8+F8)-(C8+E8),0)
A9: 31 | B9: Merchandise inventory | C9: =SUMIFS(Journal!$F:$F,Journal!$C:$C,A9,Journal!$B:$B,"OUV") | D9: =SUMIFS(Journal!$G:$G,Journal!$C:$C,A9,Journal!$B:$B,"OUV") | E9: =SUMIFS(Journal!$F:$F,Journal!$C:$C,A9,Journal!$B:$B,"<>OUV") | F9: =SUMIFS(Journal!$G:$G,Journal!$C:$C,A9,Journal!$B:$B,"<>OUV") | G9: =IF((C9+E9)-(D9+F9)>0,(C9+E9)-(D9+F9),0) | H9: =IF((D9+F9)-(C9+E9)>0,(D9+F9)-(C9+E9),0)
A10: 401 | B10: Trade payables | C10: =SUMIFS(Journal!$F:$F,Journal!$C:$C,A10,Journal!$B:$B,"OUV") | D10: =SUMIFS(Journal!$G:$G,Journal!$C:$C,A10,Journal!$B:$B,"OUV") | E10: =SUMIFS(Journal!$F:$F,Journal!$C:$C,A10,Journal!$B:$B,"<>OUV") | F10: =SUMIFS(Journal!$G:$G,Journal!$C:$C,A10,Journal!$B:$B,"<>OUV") | G10: =IF((C10+E10)-(D10+F10)>0,(C10+E10)-(D10+F10),0) | H10: =IF((D10+F10)-(C10+E10)>0,(D10+F10)-(C10+E10),0)
A11: 411 | B11: Trade receivables | C11: =SUMIFS(Journal!$F:$F,Journal!$C:$C,A11,Journal!$B:$B,"OUV") | D11: =SUMIFS(Journal!$G:$G,Journal!$C:$C,A11,Journal!$B:$B,"OUV") | E11: =SUMIFS(Journal!$F:$F,Journal!$C:$C,A11,Journal!$B:$B,"<>OUV") | F11: =SUMIFS(Journal!$G:$G,Journal!$C:$C,A11,Journal!$B:$B,"<>OUV") | G11: =IF((C11+E11)-(D11+F11)>0,(C11+E11)-(D11+F11),0) | H11: =IF((D11+F11)-(C11+E11)>0,(D11+F11)-(C11+E11),0)
A12: 44 | B12: State, income tax | C12: =SUMIFS(Journal!$F:$F,Journal!$C:$C,A12,Journal!$B:$B,"OUV") | D12: =SUMIFS(Journal!$G:$G,Journal!$C:$C,A12,Journal!$B:$B,"OUV") | E12: =SUMIFS(Journal!$F:$F,Journal!$C:$C,A12,Journal!$B:$B,"<>OUV") | F12: =SUMIFS(Journal!$G:$G,Journal!$C:$C,A12,Journal!$B:$B,"<>OUV") | G12: =IF((C12+E12)-(D12+F12)>0,(C12+E12)-(D12+F12),0) | H12: =IF((D12+F12)-(C12+E12)>0,(D12+F12)-(C12+E12),0)
A13: 52 | B13: Banks | C13: =SUMIFS(Journal!$F:$F,Journal!$C:$C,A13,Journal!$B:$B,"OUV") | D13: =SUMIFS(Journal!$G:$G,Journal!$C:$C,A13,Journal!$B:$B,"OUV") | E13: =SUMIFS(Journal!$F:$F,Journal!$C:$C,A13,Journal!$B:$B,"<>OUV") | F13: =SUMIFS(Journal!$G:$G,Journal!$C:$C,A13,Journal!$B:$B,"<>OUV") | G13: =IF((C13+E13)-(D13+F13)>0,(C13+E13)-(D13+F13),0) | H13: =IF((D13+F13)-(C13+E13)>0,(D13+F13)-(C13+E13),0)
A14: 601 | B14: Purchases of goods | C14: =SUMIFS(Journal!$F:$F,Journal!$C:$C,A14,Journal!$B:$B,"OUV") | D14: =SUMIFS(Journal!$G:$G,Journal!$C:$C,A14,Journal!$B:$B,"OUV") | E14: =SUMIFS(Journal!$F:$F,Journal!$C:$C,A14,Journal!$B:$B,"<>OUV") | F14: =SUMIFS(Journal!$G:$G,Journal!$C:$C,A14,Journal!$B:$B,"<>OUV") | G14: =IF((C14+E14)-(D14+F14)>0,(C14+E14)-(D14+F14),0) | H14: =IF((D14+F14)-(C14+E14)>0,(D14+F14)-(C14+E14),0)
... A21: 891 | B21: Income tax | C21: =SUMIFS(Journal!$F:$F,Journal!$C:$C,A21,Journal!$B:$B,"OUV") | D21: =SUMIFS(Journal!$G:$G,Journal!$C:$C,A21,Journal!$B:$B,"OUV") | E21: =SUMIFS(Journal!$F:$F,Journal!$C:$C,A21,Journal!$B:$B,"<>OUV") | F21: =SUMIFS(Journal!$G:$G,Journal!$C:$C,A21,Journal!$B:$B,"<>OUV") | G21: =IF((C21+E21)-(D21+F21)>0,(C21+E21)-(D21+F21),0) | H21: =IF((D21+F21)-(C21+E21)>0,(D21+F21)-(C21+E21),0)
B22: TOTALS | C22: =SUM(C3:C21) | D22: =SUM(D3:D21) | E22: =SUM(E3:E21) | F22: =SUM(F3:F21) | G22: =SUM(G3:G21) | H22: =SUM(H3:H21)

Sheet Resultat
A1: OHADA INCOME STATEMENT (Intermediate Management Balances) - 2025
A2: Item | B2: Amount
A3: Sales of goods | B3: =Balance!H20
A4: Purchases of goods | B4: =-Balance!G14
A5: Change in merchandise inventory | B5: =-(Balance!G15-Balance!H15)
A6: GROSS TRADING MARGIN | B6: =B3+B4+B5
A7: External services | B7: =-Balance!G16
A8: VALUE ADDED | B8: =B6+B7
A9: Personnel expenses | B9: =-Balance!G17
A10: GROSS OPERATING SURPLUS (EBITDA) | B10: =B8+B9
A11: Depreciation allowances | B11: =-Balance!G19
A12: OPERATING PROFIT | B12: =B10+B11
A13: Financial expenses | B13: =-Balance!G18
A14: FINANCIAL RESULT | B14: =B13
A15: PROFIT FROM ORDINARY ACTIVITIES | B15: =B12+B14
A16: Result from extraordinary items | B16: =0
A17: PROFIT BEFORE TAX | B17: =B15+B16
A18: Income tax | B18: =-Balance!G21
A19: NET PROFIT FOR THE YEAR | B19: =B17+B18

Sheet Bilan
A1: OHADA BALANCE SHEET as at 31/12/2025
A2: ASSETS | B2: Gross | C2: Depr./Amort. | D2: Net
A3: Non-current assets
A4: Property, plant and equipment | B4: =Balance!G7 | C4: =Balance!H8 | D4: =B4-C4
A5: Total non-current assets | D5: =D4
A6: Current assets
A7: Merchandise inventory | B7: =Balance!G9 | C7: =0 | D7: =B7-C7
A8: Trade receivables | B8: =Balance!G11 | C8: =0 | D8: =B8-C8
A9: Total current assets | D9: =D7+D8
A10: Cash assets
A11: Banks | B11: =Balance!G13 | C11: =0 | D11: =B11-C11
A12: Total cash assets | D12: =D11
A13: TOTAL ASSETS | B13: =B4+B7+B8+B11 | C13: =C4 | D13: =D5+D9+D12
A15: EQUITY & LIABILITIES | D15: Net
A16: Equity
A17: Share capital | D17: =Balance!H3
A18: Reserves | D18: =Balance!H4
A19: Retained earnings | D19: =Balance!H5-Balance!G5
A20: Net profit for the year | D20: =Resultat!B19
A21: Total equity | D21: =D17+D18+D19+D20
A22: Financial liabilities
A23: Borrowings | D23: =Balance!H6
A24: Total financial liabilities | D24: =D23
A25: Current liabilities
A26: Trade payables | D26: =Balance!H10
A27: State, income tax | D27: =Balance!H12
A28: Total current liabilities | D28: =D26+D27
A29: TOTAL EQUITY & LIABILITIES | D29: =D21+D24+D28
A30: Check (Assets - Liabilities) | D30: =D13-D29

Sheet Tresorerie
A1: OHADA STATEMENT OF CASH FLOWS (indirect) - 2025
A2: Item | B2: Amount | D2: Opening balances (01/01) | E2: Value
A3: Operating activities | D3: Trade receivables | E3: 30000
A4: Profit before tax | B4: =Resultat!B17 | D4: Inventory | E4: 40000
A5: + Depreciation allowances | B5: =Balance!G19 | D5: Trade payables | E5: 25000
A6: + Financial expenses | B6: =Balance!G18 | D6: PP&E (gross) | E6: 200000
A7: Profit before working capital changes | B7: =B4+B5+B6 | D7: Borrowings | E7: 80000
A8: Change in receivables | B8: =-(Balance!G11-E3) | D8: Banks | E8: 50000
A9: Change in inventory | B9: =-(Balance!G9-E4) | D9: Retained earnings | E9: 15000
A10: Change in payables | B10: =Balance!H10-E5
A11: Cash generated from operations | B11: =B7+B8+B9+B10
A12: Interest paid | B12: =-Balance!G18
A13: Income tax paid | B13: =-(Balance!G21-Balance!H12)
A14: Net operating cash flow | B14: =B11+B12+B13
A15: Investing activities
A16: Purchase of PP&E | B16: =-(Balance!G7-E6)
A17: Net investing cash flow | B17: =B16
A18: Financing activities
A19: Change in borrowings | B19: =Balance!H6-E7
A20: Dividends paid | B20: =-(E9-(Balance!H5-Balance!G5))
A21: Net financing cash flow | B21: =B19+B20
A22: Net change in cash | B22: =B14+B17+B21
A23: Opening cash | B23: =E8
A24: Closing cash | B24: =B23+B22
A25: Check (vs balance sheet) | B25: =B24-Balance!G13

Sheet Notes
A1: NOTES TO THE FINANCIAL STATEMENTS - Year ended 31/12/2025
A3: NOTE 1 - ACCOUNTING PRINCIPLES AND METHODS
A4: The financial statements are prepared in accordance with the revised SYSCOHADA accounting framework. They are presented in CFA francs (FCFA) and cover the year ended 31 December 2025.
A5: General measurement basis: historical cost. Property, plant and equipment is depreciated on a straight-line basis over its estimated useful life. Inventories are measured at weighted average cost (WAC) and written down to net realisable value where lower than cost.
A7: NOTE 2 - PROPERTY, PLANT AND EQUIPMENT
A8: Item | B8: Gross opening | C8: Additions | D8: Disposals | E8: Gross closing | F8: Depr. opening | G8: Charge for year | H8: Depr. closing | I8: NBV closing
A9: Property, plant and equipment | B9: =Balance!C7 | C9: =Balance!E7 | D9: =Balance!F7 | E9: =Balance!G7 | F9: =Balance!D8 | G9: =Balance!F8 | H9: =Balance!H8 | I9: =E9-H9
A11: NOTE 3 - INVENTORIES
A12: Item | B12: Opening | C12: Net decrease | D12: Closing
A13: Merchandise inventory | B13: =Balance!C9 | C13: =Balance!F9 | D13: =Balance!G9
A15: NOTE 4 - TRADE RECEIVABLES
A16: Item | B16: Opening | C16: Sales for year | D16: Collections | E16: Closing
A17: Trade receivables | B17: =Balance!C11 | C17: =Balance!E11 | D17: =Balance!F11 | E17: =Balance!G11
A18: Ageing analysis not detailed in this example. No receivable has been identified as doubtful or impaired at year-end.
A20: NOTE 5 - CASH AND CASH EQUIVALENTS
A21: Item | B21: Opening | C21: Inflows | D21: Outflows | E21: Closing
A22: Banks | B22: =Balance!C13 | C22: =Balance!E13 | D22: =Balance!F13 | E22: =Balance!G13
A24: NOTE 6 - STATEMENT OF CHANGES IN EQUITY
A25: Item | B25: Capital | C25: Reserves | D25: Retained earnings | E25: Net result | F25: Total
A26: Balance at 01/01/2025 | B26: =Balance!D3 | C26: =Balance!D4 | D26: =Balance!D5 | E26: 0 | F26: =B26+C26+D26+E26
A27: Dividends paid | B27: 0 | C27: 0 | D27: =-Balance!E5 | E27: 0 | F27: =B27+C27+D27+E27
A28: Net result for the year | B28: 0 | C28: 0 | D28: 0 | E28: =Resultat!B19 | F28: =B28+C28+D28+E28
A29: Balance at 31/12/2025 | B29: =Balance!H3 | C29: =Balance!H4 | D29: =Balance!H5-Balance!G5 | E29: =Resultat!B19 | F29: =Bilan!D21
A31: NOTE 7 - BORROWINGS AND FINANCIAL LIABILITIES
A32: Item | B32: Opening | C32: New borrowings | D32: Repayments | E32: Closing
A33: Borrowings | B33: =Balance!D6 | C33: =Balance!F6 | D33: =Balance!E6 | E33: =Balance!H6
A34: As a simplifying assumption for this example, the entire balance at 31/12/2025 is presented as non-current financial liabilities; no detailed repayment schedule is available.
A36: NOTE 8 - TRADE PAYABLES AND OTHER LIABILITIES
A37: Item | B37: Opening | C37: Debit mvts | D37: Credit mvts | E37: Closing
A38: Trade payables | B38: =Balance!D10 | C38: =Balance!E10 | D38: =Balance!F10 | E38: =Balance!H10
A39: State, income tax | B39: =Balance!D12 | C39: =Balance!E12 | D39: =Balance!F12 | E39: =Balance!H12
A41: NOTE 9 - PROVISIONS AND OFF-BALANCE SHEET COMMITMENTS
A42: No provision for contingencies has been recognised for the year. No significant off-balance sheet commitment (guarantees given, sureties, finance lease commitments) has been identified at year-end.
A44: NOTE 10 - INCOME TAX
A45: Item | B45: Amount
A46: Profit before tax | B46: =Resultat!B17
A47: Income tax expense | B47: =Resultat!B18
A48: Effective tax rate | B48: =-B47/B46
A50: NOTE 11 - PERSONNEL EXPENSES
A51: Item | B51: Amount
...

Sheet Ratios
A1: OHADA FINANCIAL RATIOS - Year 2025
A2: Ratio | B2: Value | C2: Formula / interpretation
A3: Current ratio | B3: =(Bilan!D9+Bilan!D12)/Bilan!D28 | C3: (Current assets + Cash) / Current liabilities
A4: Quick ratio | B4: =(Bilan!D9+Bilan!D12-Bilan!D7)/Bilan!D28 | C4: excl. inventory / Current liabilities
A5: Financial autonomy | B5: =Bilan!D21/Bilan!D13 | C5: Equity / Total assets
A6: Gearing (Debt/Equity) | B6: =Bilan!D24/Bilan!D21 | C6: Borrowings / Equity
A7: Gross trading margin rate | B7: =Resultat!B6/Resultat!B3 | C7: Trading margin / Sales
A8: Value added rate | B8: =Resultat!B8/Resultat!B3 | C8: Value added / Sales
A9: Net margin | B9: =Resultat!B19/Resultat!B3 | C9: Net profit / Sales
A10: Return on equity (ROE) | B10: =Resultat!B19/Bilan!D21 | C10: Net profit / Equity
A11: Return on assets (ROA) | B11: =Resultat!B19/Bilan!D13 | C11: Net profit / Total assets
A12: Inventory turnover | B12: =-(Resultat!B4+Resultat!B5)/Bilan!D7 | C12: Cost of goods sold / Inventory
A13: Working capital requirement | B13: =Bilan!D7+Bilan!D8-Bilan!D26 | C13: Inventory + Receivables - Payables

Sheet Graphiques
A1: CHARTS - DASHBOARD 2025
A3: MONTHLY EVOLUTION (cumulative)
A4: Month | B4: Jan | C4: Feb | D4: Mar | E4: Apr | F4: May | G4: Jun | H4: Jul | I4: Aug | J4: Sep | K4: Oct | L4: Nov | M4: Dec
A5: Month No. | B5: 1 | C5: 2 | D5: 3 | E5: 4 | F5: 5 | G5: 6 | H5: 7 | I5: 8 | J5: 9 | K5: 10 | L5: 11 | M5: 12
A6: Cumulative Sales | B6: =SUMIFS(Journal!$G:$G,Journal!$C:$C,701,Journal!$H:$H,"<="&B$5) | C6: =SUMIFS(Journal!$G:$G,Journal!$C:$C,701,Journal!$H:$H,"<="&C$5) | D6: =SUMIFS(Journal!$G:$G,Journal!$C:$C,701,Journal!$H:$H,"<="&D$5) | E6: =SUMIFS(Journal!$G:$G,Journal!$C:$C,701,Journal!$H:$H,"<="&E$5) | F6: =SUMIFS(Journal!$G:$G,Journal!$C:$C,701,Journal!$H:$H,"<="&F$5) | G6: =SUMIFS(Journal!$G:$G,Journal!$C:$C,701,Journal!$H:$H,"<="&G$5) | H6: =SUMIFS(Journal!$G:$G,Journal!$C:$C,701,Journal!$H:$H,"<="&H$5) | I6: =SUMIFS(Journal!$G:$G,Journal!$C:$C,701,Journal!$H:$H,"<="&I$5) | ... M6: =SUMIFS(Journal!$G:$G,Journal!$C:$C,701,Journal!$H:$H,"<="&M$5)
A7: Cumulative Net Result | B7: =SUMIFS(Journal!$G:$G,Journal!$C:$C,701,Journal!$H:$H,"<="&B$5)-SUMIFS(Journal!$F:$F,Journal!$C:$C,601,Journal!$H:$H,"<="&B$5)-(SUMIFS(Journal!$F:$F,Journal!$C:$C,6031,Journal!$H:$H,"<="&B$5)-SUMIFS(Journal!$G:$G,Journal!$C:$C,6031,Journal!$H:$H,"<="&B$5))-SUMIFS(Journal!$F:$F,Journal!$C:$C,62,Journal!$H:$H,"<="&B$5)-SUMIFS(Journal!$F:$F,Journal!$C:$C,66,Journal!$H:$H,"<="&B$5)-SUMIFS(Journal!$F:$F,Journal!$C:$C,681,Journal!$H:$H,"<="&B$5)-SUMIFS(Journal!$F:$F,Journal!$C:$C,671,Journal!$H:$H,"<="&B$5)-SUMIFS(Journal!$F:$F,Journal!$C:$C,891,Journal!$H:$H,"<="&B$5) | C7: =SUMIFS(Journal!$G:$G,Journal!$C:$C,701,Journal!$H:$H,"<="&C$5)-SUMIFS(Journal!$F:$F,Journal!$C:$C,601,Journal!$H:$H,"<="&C$5)-(SUMIFS(Journal!$F:$F,Journal!$C:$C,6031,Journal!$H:$H,"<="&C$5)-SUMIFS(Journal!$G:$G,Journal!$C:$C,6031,Journal!$H:$H,"<="&C$5))-SUMIFS(Journal!$F:$F,Journal!$C:$C,62,Journal!$H:$H,"<="&C$5)-SUMIFS(Journal!$F:$F,Journal!$C:$C,66,Journal!$H:$H,"<="&C$5)-SUMIFS(Journal!$F:$F,Journal!$C:$C,681,Journal!$H:$H,"<="&C$5)-SUMIFS(Journal!$F:$F,Journal!$C:$C,671,Journal!$H:$H,"<="&C$5)-SUMIFS(Journal!$F:$F,Journal!$C:$C,891,Journal!$H:$H,"<="&C$5) | D7: =SUMIFS(Journal!$G:$G,Journal!$C:$C,701,Journal!$H:$H,"<="&D$5)-SUMIFS(Journal!$F:$F,Journal!$C:$C,601,Journal!$H:$H,"<="&D$5)-(SUMIFS(Journal!$F:$F,Journal!$C:$C,6031,Journal!$H:$H,"<="&D$5)-SUMIFS(Journal!$G:$G,Journal!$C:$C,6031,Journal!$H:$H,"<="&D$5))-SUMIFS(Journal!$F:$F,Journal!$C:$C,62,Journal!$H:$H,"<="&D$5)-SUMIFS(Journal!$F:$F,Journal!$C:$C,66,Journal!$H:$H,"<="&D$5)-SUMIFS(Journal!$F:$F,Journal!$C:$C,681,Journal!$H:$H,"<="&D$5)-SUMIFS(Journal!$F:$F,Journal!$C:$C,671,Journal!$H:$H,"<="&D$5)-SUMIFS(Journal!$F:$F,Journal!$C:$C,891,Journal!$H:$H,"<="&D$5) | E7: =SUMIFS(Journal!$G:$G,Journal!$C:$C,701,Journal!$H:$H,"<="&E$5)-SUMIFS(Journal!$F:$F,Journal!$C:$C,601,Journal!$H:$H,"<="&E$5)-(SUMIFS(Journal!$F:$F,Journal!$C:$C,6031,Journal!$H:$H,"<="&E$5)-SUMIFS(Journal!$G:$G,Journal!$C:$C,6031,Journal!$H:$H,"<="&E$5))-SUMIFS(Journal!$F:$F,Journal!$C:$C,62,Journal!$H:$H,"<="&E$5)-SUMIFS(Journal!$F:$F,Journal!$C:$C,66,Journal!$H:$H,"<="&E$5)-SUMIFS(Journal!$F:$F,Journal!$C:$C,681,Journal!$H:$H,"<="&E$5)-SUMIFS(Journal!$F:$F,Journal!$C:$C,671,Journal!$H:$H,"<="&E$5)-SUMIFS(Journal!$F:$F,Journal!$C:$C,891,Journal!$H:$H,"<="&E$5) | F7: =SUMIFS(Journal!$G:$G,Journal!$C:$C,701,Journal!$H:$H,"<="&F$5)-SUMIFS(Journal!$F:$F,Journal!$C:$C,601,Journal!$H:$H,"<="&F$5)-(SUMIFS(Journal!$F:$F,Journal!$C:$C,6031,Journal!$H:$H,"<="&F$5)-SUMIFS(Journal!$G:$G,Journal!$C:$C,6031,Journal!$H:$H,"<="&F$5))-SUMIFS(Journal!$F:$F,Journal!$C:$C,62,Journal!$H:$H,"<="&F$5)-SUMIFS(Journal!$F:$F,Journal!$C:$C,66,Journal!$H:$H,"<="&F$5)-SUMIFS(Journal!$F:$F,Journal!$C:$C,681,Journal!$H:$H,"<="&F$5)-SUMIFS(Journal!$F:$F,Journal!$C:$C,671,Journal!$H:$H,"<="&F$5)-SUMIFS(Journal!$F:$F,Journal!$C:$C,891,Journal!$H:$H,"<="&F$5) | G7: =SUMIFS(Journal!$G:$G,Journal!$C:$C,701,Journal!$H:$H,"<="&G$5)-SUMIFS(Journal!$F:$F,Journal!$C:$C,601,Journal!$H:$H,"<="&G$5)-(SUMIFS(Journal!$F:$F,Journal!$C:$C,6031,Journal!$H:$H,"<="&G$5)-SUMIFS(Journal!$G:$G,Journal!$C:$C,6031,Journal!$H:$H,"<="&G$5))-SUMIFS(Journal!$F:$F,Journal!$C:$C,62,Journal!$H:$H,"<="&G$5)-SUMIFS(Journal!$F:$F,Journal!$C:$C,66,Journal!$H:$H,"<="&G$5)-SUMIFS(Journal!$F:$F,Journal!$C:$C,681,Journal!$H:$H,"<="&G$5)-SUMIFS(Journal!$F:$F,Journal!$C:$C,671,Journal!$H:$H,"<="&G$5)-SUMIFS(Journal!$F:$F,Journal!$C:$C,891,Journal!$H:$H,"<="&G$5) | H7: =SUMIFS(Journal!$G:$G,Journal!$C:$C,701,Journal!$H:$H,"<="&H$5)-SUMIFS(Journal!$F:$F,Journal!$C:$C,601,Journal!$H:$H,"<="&H$5)-(SUMIFS(Journal!$F:$F,Journal!$C:$C,6031,Journal!$H:$H,"<="&H$5)-SUMIFS(Journal!$G:$G,Journal!$C:$C,6031,Journal!$H:$H,"<="&H$5))-SUMIFS(Journal!$F:$F,Journal!$C:$C,62,Journal!$H:$H,"<="&H$5)-SUMIFS(Journal!$F:$F,Journal!$C:$C,66,Journal!$H:$H,"<="&H$5)-SUMIFS(Journal!$F:$F,Journal!$C:$C,681,Journal!$H:$H,"<="&H$5)-SUMIFS(Journal!$F:$F,Journal!$C:$C,671,Journal!$H:$H,"<="&H$5)-SUMIFS(Journal!$F:$F,Journal!$C:$C,891,Journal!$H:$H,"<="&H$5) | I7: =SUMIFS(Journal!$G:$G,Journal!$C:$C,701,Journal!$H:$H,"<="&I$5)-SUMIFS(Journal!$F:$F,Journal!$C:$C,601,Journal!$H:$H,"<="&I$5)-(SUMIFS(Journal!$F:$F,Journal!$C:$C,6031,Journal!$H:$H,"<="&I$5)-SUMIFS(Journal!$G:$G,Journal!$C:$C,6031,Journal!$H:$H,"<="&I$5))-SUMIFS(Journal!$F:$F,Journal!$C:$C,62,Journal!$H:$H,"<="&I$5)-SUMIFS(Journal!$F:$F,Journal!$C:$C,66,Journal!$H:$H,"<="&I$5)-SUMIFS(Journal!$F:$F,Journal!$C:$C,681,Journal!$H:$H,"<="&I$5)-SUMIFS(Journal!$F:$F,Journal!$C:$C,671,Journal!$H:$H,"<="&I$5)-SUMIFS(Journal!$F:$F,Journal!$C:$C,891,Journal!$H:$H,"<="&I$5) | ... M7: =SUMIFS(Journal!$G:$G,Journal!$C:$C,701,Journal!$H:$H,"<="&M$5)-SUMIFS(Journal!$F:$F,Journal!$C:$C,601,Journal!$H:$H,"<="&M$5)-(SUMIFS(Journal!$F:$F,Journal!$C:$C,6031,Journal!$H:$H,"<="&M$5)-SUMIFS(Journal!$G:$G,Journal!$C:$C,6031,Journal!$H:$H,"<="&M$5))-SUMIFS(Journal!$F:$F,Journal!$C:$C,62,Journal!$H:$H,"<="&M$5)-SUMIFS(Journal!$F:$F,Journal!$C:$C,66,Journal!$H:$H,"<="&M$5)-SUMIFS(Journal!$F:$F,Journal!$C:$C,681,Journal!$H:$H,"<="&M$5)-SUMIFS(Journal!$F:$F,Journal!$C:$C,671,Journal!$H:$H,"<="&M$5)-SUMIFS(Journal!$F:$F,Journal!$C:$C,891,Journal!$H:$H,"<="&M$5)
A8: Cash (Banks) | B8: =SUMIFS(Journal!$F:$F,Journal!$C:$C,52,Journal!$H:$H,"<="&B$5)-SUMIFS(Journal!$G:$G,Journal!$C:$C,52,Journal!$H:$H,"<="&B$5) | C8: =SUMIFS(Journal!$F:$F,Journal!$C:$C,52,Journal!$H:$H,"<="&C$5)-SUMIFS(Journal!$G:$G,Journal!$C:$C,52,Journal!$H:$H,"<="&C$5) | D8: =SUMIFS(Journal!$F:$F,Journal!$C:$C,52,Journal!$H:$H,"<="&D$5)-SUMIFS(Journal!$G:$G,Journal!$C:$C,52,Journal!$H:$H,"<="&D$5) | E8: =SUMIFS(Journal!$F:$F,Journal!$C:$C,52,Journal!$H:$H,"<="&E$5)-SUMIFS(Journal!$G:$G,Journal!$C:$C,52,Journal!$H:$H,"<="&E$5) | F8: =SUMIFS(Journal!$F:$F,Journal!$C:$C,52,Journal!$H:$H,"<="&F$5)-SUMIFS(Journal!$G:$G,Journal!$C:$C,52,Journal!$H:$H,"<="&F$5) | G8: =SUMIFS(Journal!$F:$F,Journal!$C:$C,52,Journal!$H:$H,"<="&G$5)-SUMIFS(Journal!$G:$G,Journal!$C:$C,52,Journal!$H:$H,"<="&G$5) | H8: =SUMIFS(Journal!$F:$F,Journal!$C:$C,52,Journal!$H:$H,"<="&H$5)-SUMIFS(Journal!$G:$G,Journal!$C:$C,52,Journal!$H:$H,"<="&H$5) | I8: =SUMIFS(Journal!$F:$F,Journal!$C:$C,52,Journal!$H:$H,"<="&I$5)-SUMIFS(Journal!$G:$G,Journal!$C:$C,52,Journal!$H:$H,"<="&I$5) | ... M8: =SUMIFS(Journal!$F:$F,Journal!$C:$C,52,Journal!$H:$H,"<="&M$5)-SUMIFS(Journal!$G:$G,Journal!$C:$C,52,Journal!$H:$H,"<="&M$5)
A10: BALANCE SHEET STRUCTURE (31/12/2025)
A11: Item | B11: Amount
A12: Non-current assets | B12: =Bilan!D5
A13: Current assets | B13: =Bilan!D9
A14: Cash assets | B14: =Bilan!D12
A15: Equity | B15: =Bilan!D21
A16: Financial liabilities | B16: =Bilan!D24
A17: Current liabilities | B17: =Bilan!D28
A19: KEY RATIOS
A20: Ratio | B20: Value
A21: Financial autonomy | B21: =Ratios!B5
A22: Gross trading margin rate | B22: =Ratios!B7
A23: Value added rate | B23: =Ratios!B8
A24: Net margin | B24: =Ratios!B9
A25: Return on equity (ROE) | B25: =Ratios!B10
A26: Return on assets (ROA) | B26: =Ratios!B11
